2020-12-22 20:16:32,380 [Thread-1:14596] [django.request:230] [log:log_response] [ERROR]- Internal Server Error: /uploadFiles
Traceback (most recent call last):
  File "C:\Users\TJ\PycharmProjects\SharePlatform\venv\lib\site-packages\django\core\handlers\exception.py", line 47, in inner
    response = get_response(request)
  File "C:\Users\TJ\PycharmProjects\SharePlatform\venv\lib\site-packages\django\core\handlers\base.py", line 179, in _get_response
    response = wrapped_callback(request, *callback_args, **callback_kwargs)
  File "C:\Users\TJ\PycharmProjects\SharePlatform\venv\lib\site-packages\django\views\decorators\csrf.py", line 54, in wrapped_view
    return view_func(*args, **kwargs)
  File "C:\Users\TJ\PycharmProjects\SharePlatform\venv\lib\site-packages\django\views\generic\base.py", line 70, in view
    return self.dispatch(request, *args, **kwargs)
  File "C:\Users\TJ\PycharmProjects\SharePlatform\venv\lib\site-packages\django\views\decorators\csrf.py", line 54, in wrapped_view
    return view_func(*args, **kwargs)
  File "C:\Users\TJ\PycharmProjects\SharePlatform\resource\views.py", line 65, in dispatch
    return super(FileUploadView, self).dispatch(request,*args, **kwargs)
  File "C:\Users\TJ\PycharmProjects\SharePlatform\venv\lib\site-packages\rest_framework\views.py", line 509, in dispatch
    response = self.handle_exception(exc)
  File "C:\Users\TJ\PycharmProjects\SharePlatform\venv\lib\site-packages\rest_framework\views.py", line 469, in handle_exception
    self.raise_uncaught_exception(exc)
  File "C:\Users\TJ\PycharmProjects\SharePlatform\venv\lib\site-packages\rest_framework\views.py", line 480, in raise_uncaught_exception
    raise exc
  File "C:\Users\TJ\PycharmProjects\SharePlatform\venv\lib\site-packages\rest_framework\views.py", line 506, in dispatch
    response = handler(request, *args, **kwargs)
  File "C:\Users\TJ\PycharmProjects\SharePlatform\login\login_token.py", line 71, in resolve_token1
    return func(self,request,args)
  File "C:\Users\TJ\PycharmProjects\SharePlatform\resource\views.py", line 44, in post
    file_owner = Teacher.objects.get(uid = args.get('uid'))
  File "C:\Users\TJ\PycharmProjects\SharePlatform\venv\lib\site-packages\mongoengine\queryset\base.py", line 260, in get
    result = next(queryset)
  File "C:\Users\TJ\PycharmProjects\SharePlatform\venv\lib\site-packages\mongoengine\queryset\base.py", line 1590, in __next__
    raw_doc = next(self._cursor)
  File "C:\Users\TJ\PycharmProjects\SharePlatform\venv\lib\site-packages\mongoengine\queryset\base.py", line 1666, in _cursor
    self._cursor_obj = self._collection.find(self._query, **self._cursor_args)
  File "C:\Users\TJ\PycharmProjects\SharePlatform\venv\lib\site-packages\mongoengine\queryset\base.py", line 1715, in _query
    self._mongo_query = self._query_obj.to_query(self._document)
  File "C:\Users\TJ\PycharmProjects\SharePlatform\venv\lib\site-packages\mongoengine\queryset\visitor.py", line 90, in to_query
    query = query.accept(QueryCompilerVisitor(document))
  File "C:\Users\TJ\PycharmProjects\SharePlatform\venv\lib\site-packages\mongoengine\queryset\visitor.py", line 185, in accept
    return visitor.visit_query(self)
  File "C:\Users\TJ\PycharmProjects\SharePlatform\venv\lib\site-packages\mongoengine\queryset\visitor.py", line 79, in visit_query
    return transform.query(self.document, **query.query)
  File "C:\Users\TJ\PycharmProjects\SharePlatform\venv\lib\site-packages\mongoengine\queryset\transform.py", line 120, in query
    value = field.prepare_query_value(op, value)
  File "C:\Users\TJ\PycharmProjects\SharePlatform\venv\lib\site-packages\mongoengine\fields.py", line 2174, in prepare_query_value
    return self.value_decorator(value)
TypeError: int() argument must be a string, a bytes-like object or a number, not 'NoneType'
2020-12-22 20:22:46,663 [Thread-4:16356] [django.request:230] [log:log_response] [WARNING]- Not Found: /file/高级数据库技术/分布式数据库系统及其应用(jb51.net).pdf
2020-12-22 20:23:03,903 [Thread-4:16356] [django.request:230] [log:log_response] [WARNING]- Not Found: /file/test.txt
2020-12-22 20:56:03,138 [Thread-2:6444] [django.request:230] [log:log_response] [WARNING]- Not Found: /favicon.ico
2020-12-22 21:06:42,936 [Thread-1:16396] [django.request:230] [log:log_response] [WARNING]- Not Found: /login
2020-12-22 21:07:33,431 [Thread-1:16448] [django.request:230] [log:log_response] [WARNING]- Not Found: /login
2020-12-22 21:08:06,785 [Thread-1:16448] [django.request:230] [log:log_response] [ERROR]- Internal Server Error: /api/login
Traceback (most recent call last):
  File "C:\Users\TJ\PycharmProjects\SharePlatform\venv\lib\site-packages\django\core\handlers\exception.py", line 47, in inner
    response = get_response(request)
  File "C:\Users\TJ\PycharmProjects\SharePlatform\venv\lib\site-packages\django\utils\deprecation.py", line 113, in __call__
    response = self.process_request(request)
  File "C:\Users\TJ\PycharmProjects\SharePlatform\venv\lib\site-packages\django\middleware\common.py", line 54, in process_request
    path = self.get_full_path_with_slash(request)
  File "C:\Users\TJ\PycharmProjects\SharePlatform\venv\lib\site-packages\django\middleware\common.py", line 94, in get_full_path_with_slash
    'url': request.get_host() + new_path,
RuntimeError: You called this URL via POST, but the URL doesn't end in a slash and you have APPEND_SLASH set. Django can't redirect to the slash URL while maintaining POST data. Change your form to point to 127.0.0.1:8000/api/login/ (note the trailing slash), or set APPEND_SLASH=False in your Django settings.
2020-12-22 21:09:17,663 [Thread-2:15916] [django.request:230] [log:log_response] [WARNING]- Not Found: /course/
2020-12-22 21:11:23,411 [Thread-1:11056] [django.request:230] [log:log_response] [ERROR]- Internal Server Error: /courses/
Traceback (most recent call last):
  File "C:\Users\TJ\PycharmProjects\SharePlatform\venv\lib\site-packages\django\core\handlers\exception.py", line 47, in inner
    response = get_response(request)
  File "C:\Users\TJ\PycharmProjects\SharePlatform\venv\lib\site-packages\django\core\handlers\base.py", line 179, in _get_response
    response = wrapped_callback(request, *callback_args, **callback_kwargs)
  File "C:\Users\TJ\PycharmProjects\SharePlatform\venv\lib\site-packages\django\views\decorators\csrf.py", line 54, in wrapped_view
    return view_func(*args, **kwargs)
  File "C:\Users\TJ\PycharmProjects\SharePlatform\venv\lib\site-packages\django\views\generic\base.py", line 70, in view
    return self.dispatch(request, *args, **kwargs)
  File "C:\Users\TJ\PycharmProjects\SharePlatform\venv\lib\site-packages\rest_framework\views.py", line 509, in dispatch
    response = self.handle_exception(exc)
  File "C:\Users\TJ\PycharmProjects\SharePlatform\venv\lib\site-packages\rest_framework\views.py", line 469, in handle_exception
    self.raise_uncaught_exception(exc)
  File "C:\Users\TJ\PycharmProjects\SharePlatform\venv\lib\site-packages\rest_framework\views.py", line 480, in raise_uncaught_exception
    raise exc
  File "C:\Users\TJ\PycharmProjects\SharePlatform\venv\lib\site-packages\rest_framework\views.py", line 506, in dispatch
    response = handler(request, *args, **kwargs)
  File "C:\Users\TJ\PycharmProjects\SharePlatform\course\views.py", line 47, in get
    print(courses.tojson())
AttributeError: 'QuerySet' object has no attribute 'tojson'
2020-12-22 21:11:52,890 [Thread-1:6268] [django.request:230] [log:log_response] [ERROR]- Internal Server Error: /courses/
Traceback (most recent call last):
  File "C:\Users\TJ\PycharmProjects\SharePlatform\venv\lib\site-packages\django\core\handlers\exception.py", line 47, in inner
    response = get_response(request)
  File "C:\Users\TJ\PycharmProjects\SharePlatform\venv\lib\site-packages\django\core\handlers\base.py", line 179, in _get_response
    response = wrapped_callback(request, *callback_args, **callback_kwargs)
  File "C:\Users\TJ\PycharmProjects\SharePlatform\venv\lib\site-packages\django\views\decorators\csrf.py", line 54, in wrapped_view
    return view_func(*args, **kwargs)
  File "C:\Users\TJ\PycharmProjects\SharePlatform\venv\lib\site-packages\django\views\generic\base.py", line 70, in view
    return self.dispatch(request, *args, **kwargs)
  File "C:\Users\TJ\PycharmProjects\SharePlatform\venv\lib\site-packages\rest_framework\views.py", line 509, in dispatch
    response = self.handle_exception(exc)
  File "C:\Users\TJ\PycharmProjects\SharePlatform\venv\lib\site-packages\rest_framework\views.py", line 469, in handle_exception
    self.raise_uncaught_exception(exc)
  File "C:\Users\TJ\PycharmProjects\SharePlatform\venv\lib\site-packages\rest_framework\views.py", line 480, in raise_uncaught_exception
    raise exc
  File "C:\Users\TJ\PycharmProjects\SharePlatform\venv\lib\site-packages\rest_framework\views.py", line 506, in dispatch
    response = handler(request, *args, **kwargs)
  File "C:\Users\TJ\PycharmProjects\SharePlatform\course\views.py", line 47, in get
    print(courses.tojson())
AttributeError: 'QuerySet' object has no attribute 'tojson'
2020-12-22 21:12:18,479 [Thread-1:6820] [django.request:230] [log:log_response] [ERROR]- Internal Server Error: /courses/
Traceback (most recent call last):
  File "C:\Users\TJ\PycharmProjects\SharePlatform\venv\lib\site-packages\django\core\handlers\exception.py", line 47, in inner
    response = get_response(request)
  File "C:\Users\TJ\PycharmProjects\SharePlatform\venv\lib\site-packages\django\core\handlers\base.py", line 179, in _get_response
    response = wrapped_callback(request, *callback_args, **callback_kwargs)
  File "C:\Users\TJ\PycharmProjects\SharePlatform\venv\lib\site-packages\django\views\decorators\csrf.py", line 54, in wrapped_view
    return view_func(*args, **kwargs)
  File "C:\Users\TJ\PycharmProjects\SharePlatform\venv\lib\site-packages\django\views\generic\base.py", line 70, in view
    return self.dispatch(request, *args, **kwargs)
  File "C:\Users\TJ\PycharmProjects\SharePlatform\venv\lib\site-packages\rest_framework\views.py", line 509, in dispatch
    response = self.handle_exception(exc)
  File "C:\Users\TJ\PycharmProjects\SharePlatform\venv\lib\site-packages\rest_framework\views.py", line 469, in handle_exception
    self.raise_uncaught_exception(exc)
  File "C:\Users\TJ\PycharmProjects\SharePlatform\venv\lib\site-packages\rest_framework\views.py", line 480, in raise_uncaught_exception
    raise exc
  File "C:\Users\TJ\PycharmProjects\SharePlatform\venv\lib\site-packages\rest_framework\views.py", line 506, in dispatch
    response = handler(request, *args, **kwargs)
  File "C:\Users\TJ\PycharmProjects\SharePlatform\course\views.py", line 47, in get
    print(courses.tojson())
AttributeError: 'QuerySet' object has no attribute 'tojson'
2020-12-26 12:00:28,373 [Thread-1:3180] [django.request:230] [log:log_response] [WARNING]- Method Not Allowed: /api/login/
2020-12-26 12:01:16,047 [Thread-6:18520] [django.request:230] [log:log_response] [WARNING]- Method Not Allowed: /api/login/
2020-12-26 12:01:17,991 [Thread-6:18520] [django.request:230] [log:log_response] [WARNING]- Method Not Allowed: /api/login/
2021-01-20 22:46:17,296 [Thread-1:24404] [django.request:230] [log:log_response] [ERROR]- Internal Server Error: /api/login
Traceback (most recent call last):
  File "C:\Users\TJ\PycharmProjects\SharePlatform\venv\lib\site-packages\django\core\handlers\exception.py", line 47, in inner
    response = get_response(request)
  File "C:\Users\TJ\PycharmProjects\SharePlatform\venv\lib\site-packages\django\utils\deprecation.py", line 113, in __call__
    response = self.process_request(request)
  File "C:\Users\TJ\PycharmProjects\SharePlatform\venv\lib\site-packages\django\middleware\common.py", line 54, in process_request
    path = self.get_full_path_with_slash(request)
  File "C:\Users\TJ\PycharmProjects\SharePlatform\venv\lib\site-packages\django\middleware\common.py", line 94, in get_full_path_with_slash
    'url': request.get_host() + new_path,
RuntimeError: You called this URL via POST, but the URL doesn't end in a slash and you have APPEND_SLASH set. Django can't redirect to the slash URL while maintaining POST data. Change your form to point to 127.0.0.1:8001/api/login/ (note the trailing slash), or set APPEND_SLASH=False in your Django settings.
2021-01-20 22:46:38,466 [Thread-2:25392] [django.request:230] [log:log_response] [ERROR]- Internal Server Error: /api/login
Traceback (most recent call last):
  File "C:\Users\TJ\PycharmProjects\SharePlatform\venv\lib\site-packages\django\core\handlers\exception.py", line 47, in inner
    response = get_response(request)
  File "C:\Users\TJ\PycharmProjects\SharePlatform\venv\lib\site-packages\django\utils\deprecation.py", line 113, in __call__
    response = self.process_request(request)
  File "C:\Users\TJ\PycharmProjects\SharePlatform\venv\lib\site-packages\django\middleware\common.py", line 54, in process_request
    path = self.get_full_path_with_slash(request)
  File "C:\Users\TJ\PycharmProjects\SharePlatform\venv\lib\site-packages\django\middleware\common.py", line 94, in get_full_path_with_slash
    'url': request.get_host() + new_path,
RuntimeError: You called this URL via POST, but the URL doesn't end in a slash and you have APPEND_SLASH set. Django can't redirect to the slash URL while maintaining POST data. Change your form to point to 127.0.0.1:8001/api/login/ (note the trailing slash), or set APPEND_SLASH=False in your Django settings.
2021-01-20 22:47:25,240 [Thread-3:9760] [django.request:230] [log:log_response] [ERROR]- Internal Server Error: /api/login
Traceback (most recent call last):
  File "C:\Users\TJ\PycharmProjects\SharePlatform\venv\lib\site-packages\django\core\handlers\exception.py", line 47, in inner
    response = get_response(request)
  File "C:\Users\TJ\PycharmProjects\SharePlatform\venv\lib\site-packages\django\utils\deprecation.py", line 113, in __call__
    response = self.process_request(request)
  File "C:\Users\TJ\PycharmProjects\SharePlatform\venv\lib\site-packages\django\middleware\common.py", line 54, in process_request
    path = self.get_full_path_with_slash(request)
  File "C:\Users\TJ\PycharmProjects\SharePlatform\venv\lib\site-packages\django\middleware\common.py", line 94, in get_full_path_with_slash
    'url': request.get_host() + new_path,
RuntimeError: You called this URL via POST, but the URL doesn't end in a slash and you have APPEND_SLASH set. Django can't redirect to the slash URL while maintaining POST data. Change your form to point to 127.0.0.1:8001/api/login/ (note the trailing slash), or set APPEND_SLASH=False in your Django settings.
2021-01-20 22:47:44,616 [Thread-4:21096] [django.request:230] [log:log_response] [ERROR]- Internal Server Error: /api/login
Traceback (most recent call last):
  File "C:\Users\TJ\PycharmProjects\SharePlatform\venv\lib\site-packages\django\core\handlers\exception.py", line 47, in inner
    response = get_response(request)
  File "C:\Users\TJ\PycharmProjects\SharePlatform\venv\lib\site-packages\django\utils\deprecation.py", line 113, in __call__
    response = self.process_request(request)
  File "C:\Users\TJ\PycharmProjects\SharePlatform\venv\lib\site-packages\django\middleware\common.py", line 54, in process_request
    path = self.get_full_path_with_slash(request)
  File "C:\Users\TJ\PycharmProjects\SharePlatform\venv\lib\site-packages\django\middleware\common.py", line 94, in get_full_path_with_slash
    'url': request.get_host() + new_path,
RuntimeError: You called this URL via POST, but the URL doesn't end in a slash and you have APPEND_SLASH set. Django can't redirect to the slash URL while maintaining POST data. Change your form to point to 127.0.0.1:8001/api/login/ (note the trailing slash), or set APPEND_SLASH=False in your Django settings.
2021-01-20 22:47:51,633 [Thread-5:24448] [django.request:230] [log:log_response] [ERROR]- Internal Server Error: /api/login
Traceback (most recent call last):
  File "C:\Users\TJ\PycharmProjects\SharePlatform\venv\lib\site-packages\django\core\handlers\exception.py", line 47, in inner
    response = get_response(request)
  File "C:\Users\TJ\PycharmProjects\SharePlatform\venv\lib\site-packages\django\utils\deprecation.py", line 113, in __call__
    response = self.process_request(request)
  File "C:\Users\TJ\PycharmProjects\SharePlatform\venv\lib\site-packages\django\middleware\common.py", line 54, in process_request
    path = self.get_full_path_with_slash(request)
  File "C:\Users\TJ\PycharmProjects\SharePlatform\venv\lib\site-packages\django\middleware\common.py", line 94, in get_full_path_with_slash
    'url': request.get_host() + new_path,
RuntimeError: You called this URL via POST, but the URL doesn't end in a slash and you have APPEND_SLASH set. Django can't redirect to the slash URL while maintaining POST data. Change your form to point to 127.0.0.1:8001/api/login/ (note the trailing slash), or set APPEND_SLASH=False in your Django settings.
2021-01-20 22:48:45,452 [Thread-6:23700] [django.request:230] [log:log_response] [WARNING]- Method Not Allowed: /api/login/
2021-01-20 22:49:12,551 [Thread-14:27044] [django.request:230] [log:log_response] [WARNING]- Unauthorized: /api/login/
2021-01-20 22:49:20,553 [Thread-14:27044] [django.request:230] [log:log_response] [WARNING]- Unauthorized: /api/login/
2021-01-20 22:49:29,690 [Thread-14:27044] [django.request:230] [log:log_response] [WARNING]- Unauthorized: /api/login/
2021-01-20 22:51:19,833 [Thread-15:10704] [django.request:230] [log:log_response] [WARNING]- Not Found: /api/getCateList
2021-01-20 22:51:19,863 [Thread-15:10704] [django.request:230] [log:log_response] [WARNING]- Not Found: /api/getGoodsList
2021-01-20 22:51:19,869 [Thread-15:10704] [django.request:230] [log:log_response] [WARNING]- Not Found: /api/getClassifyList
2021-01-20 23:00:11,677 [Thread-4:8296] [django.request:230] [log:log_response] [WARNING]- Method Not Allowed: /api/login/
2021-01-20 23:22:29,103 [Thread-1:18004] [django.request:230] [log:log_response] [WARNING]- Forbidden: /api/login/
2021-01-20 23:22:30,383 [Thread-1:18004] [django.request:230] [log:log_response] [WARNING]- Forbidden: /api/login/
2021-01-20 23:22:44,945 [Thread-1:18004] [django.request:230] [log:log_response] [WARNING]- Forbidden: /api/login/
2021-01-20 23:28:12,422 [Thread-1:25820] [django.request:230] [log:log_response] [WARNING]- Forbidden: /api/login/
2021-01-20 23:28:24,553 [Thread-1:25820] [django.request:230] [log:log_response] [WARNING]- Forbidden: /api/login/
2021-01-20 23:28:51,215 [Thread-1:25820] [django.request:230] [log:log_response] [WARNING]- Forbidden: /api/login/
2021-01-20 23:29:36,256 [Thread-1:25820] [django.request:230] [log:log_response] [WARNING]- Forbidden: /api/login/
2021-01-20 23:29:39,641 [Thread-1:25820] [django.request:230] [log:log_response] [WARNING]- Forbidden: /api/login/
2021-01-20 23:29:40,317 [Thread-1:25820] [django.request:230] [log:log_response] [WARNING]- Forbidden: /api/login/
2021-01-20 23:29:40,548 [Thread-1:25820] [django.request:230] [log:log_response] [WARNING]- Forbidden: /api/login/
2021-01-20 23:29:40,705 [Thread-1:25820] [django.request:230] [log:log_response] [WARNING]- Forbidden: /api/login/
2021-01-20 23:29:40,885 [Thread-1:25820] [django.request:230] [log:log_response] [WARNING]- Forbidden: /api/login/
2021-01-20 23:29:41,055 [Thread-1:25820] [django.request:230] [log:log_response] [WARNING]- Forbidden: /api/login/
2021-01-20 23:29:41,271 [Thread-1:25820] [django.request:230] [log:log_response] [WARNING]- Forbidden: /api/login/
2021-01-20 23:29:41,471 [Thread-1:25820] [django.request:230] [log:log_response] [WARNING]- Forbidden: /api/login/
2021-01-20 23:29:42,088 [Thread-1:25820] [django.request:230] [log:log_response] [WARNING]- Forbidden: /api/login/
2021-04-06 10:55:40,012 [Thread-1:107788] [django.request:230] [log:log_response] [ERROR]- Internal Server Error: /api/login
Traceback (most recent call last):
  File "C:\Users\TJ\PycharmProjects\SharePlatform\venv\lib\site-packages\django\core\handlers\exception.py", line 47, in inner
    response = get_response(request)
  File "C:\Users\TJ\PycharmProjects\SharePlatform\venv\lib\site-packages\django\utils\deprecation.py", line 113, in __call__
    response = self.process_request(request)
  File "C:\Users\TJ\PycharmProjects\SharePlatform\venv\lib\site-packages\django\middleware\common.py", line 54, in process_request
    path = self.get_full_path_with_slash(request)
  File "C:\Users\TJ\PycharmProjects\SharePlatform\venv\lib\site-packages\django\middleware\common.py", line 94, in get_full_path_with_slash
    'url': request.get_host() + new_path,
RuntimeError: You called this URL via POST, but the URL doesn't end in a slash and you have APPEND_SLASH set. Django can't redirect to the slash URL while maintaining POST data. Change your form to point to 127.0.0.1:8000/api/login/ (note the trailing slash), or set APPEND_SLASH=False in your Django settings.
2021-04-06 10:56:11,915 [Thread-2:109288] [django.request:230] [log:log_response] [ERROR]- Internal Server Error: /api/login
Traceback (most recent call last):
  File "C:\Users\TJ\PycharmProjects\SharePlatform\venv\lib\site-packages\django\core\handlers\exception.py", line 47, in inner
    response = get_response(request)
  File "C:\Users\TJ\PycharmProjects\SharePlatform\venv\lib\site-packages\django\utils\deprecation.py", line 113, in __call__
    response = self.process_request(request)
  File "C:\Users\TJ\PycharmProjects\SharePlatform\venv\lib\site-packages\django\middleware\common.py", line 54, in process_request
    path = self.get_full_path_with_slash(request)
  File "C:\Users\TJ\PycharmProjects\SharePlatform\venv\lib\site-packages\django\middleware\common.py", line 94, in get_full_path_with_slash
    'url': request.get_host() + new_path,
RuntimeError: You called this URL via POST, but the URL doesn't end in a slash and you have APPEND_SLASH set. Django can't redirect to the slash URL while maintaining POST data. Change your form to point to 127.0.0.1:8000/api/login/ (note the trailing slash), or set APPEND_SLASH=False in your Django settings.
2021-04-06 10:57:08,524 [Thread-3:103584] [django.request:230] [log:log_response] [WARNING]- Forbidden: /api/login/
